[2020-06-05 12:58:00,944] {taskinstance.py:669} INFO - Dependencies all met for <TaskInstance: covid_india_dag.source_to_csv 2020-06-05T07:26:41.848258+00:00 [queued]>
[2020-06-05 12:58:00,951] {taskinstance.py:669} INFO - Dependencies all met for <TaskInstance: covid_india_dag.source_to_csv 2020-06-05T07:26:41.848258+00:00 [queued]>
[2020-06-05 12:58:00,951] {taskinstance.py:879} INFO - 
--------------------------------------------------------------------------------
[2020-06-05 12:58:00,951] {taskinstance.py:880} INFO - Starting attempt 2 of 2
[2020-06-05 12:58:00,951] {taskinstance.py:881} INFO - 
--------------------------------------------------------------------------------
[2020-06-05 12:58:00,960] {taskinstance.py:900} INFO - Executing <Task(PythonOperator): source_to_csv> on 2020-06-05T07:26:41.848258+00:00
[2020-06-05 12:58:00,968] {standard_task_runner.py:53} INFO - Started process 3046 to run task
[2020-06-05 12:58:01,075] {logging_mixin.py:112} INFO - Running %s on host %s <TaskInstance: covid_india_dag.source_to_csv 2020-06-05T07:26:41.848258+00:00 [running]> nineleaps-ThinkPad-L470
[2020-06-05 12:58:01,460] {taskinstance.py:1145} ERROR - must be str, not HTTPError
Traceback (most recent call last):
  File "/home/nineleaps/airflow/dags/Covid_India_SampleDag.py", line 35, in get_confirmed_cases
    r.raise_for_status()
  File "/home/nineleaps/.local/lib/python3.6/site-packages/requests/models.py", line 941, in raise_for_status
    raise HTTPError(http_error_msg, response=self)
requests.exceptions.HTTPError: 404 Client Error: Not Found for url: https://api.covid19india.org/states_daily.jso

During handling of the above exception, another exception occurred:

Traceback (most recent call last):
  File "/home/nineleaps/.local/lib/python3.6/site-packages/airflow/models/taskinstance.py", line 983, in _run_raw_task
    result = task_copy.execute(context=context)
  File "/home/nineleaps/.local/lib/python3.6/site-packages/airflow/operators/python_operator.py", line 113, in execute
    return_value = self.execute_callable()
  File "/home/nineleaps/.local/lib/python3.6/site-packages/airflow/operators/python_operator.py", line 118, in execute_callable
    return self.python_callable(*self.op_args, **self.op_kwargs)
  File "/home/nineleaps/airflow/dags/Covid_India_SampleDag.py", line 70, in source_to_csv
    data = get_covid_data()
  File "/home/nineleaps/airflow/dags/Covid_India_SampleDag.py", line 62, in get_covid_data
    confirmed_case_df = get_confirmed_cases()
  File "/home/nineleaps/airflow/dags/Covid_India_SampleDag.py", line 46, in get_confirmed_cases
    logging.error("HTTP Error: " + err)
TypeError: must be str, not HTTPError
[2020-06-05 12:58:01,461] {taskinstance.py:1187} INFO - All retries failed; marking task as FAILED.dag_id=covid_india_dag, task_id=source_to_csv, execution_date=20200605T072641, start_date=20200605T072800, end_date=20200605T072801
[2020-06-05 12:58:03,200] {logging_mixin.py:112} INFO - [2020-06-05 12:58:03,199] {email.py:131} INFO - Sent an alert email to ['captaincold268@gmail.com']
[2020-06-05 12:58:10,951] {logging_mixin.py:112} INFO - [2020-06-05 12:58:10,950] {local_task_job.py:103} INFO - Task exited with return code 1
