[2020-06-03 13:35:36,801] {taskinstance.py:669} INFO - Dependencies all met for <TaskInstance: covid_dag.csv_to_table 2020-06-03T07:51:04.028764+00:00 [queued]>
[2020-06-03 13:35:36,811] {taskinstance.py:669} INFO - Dependencies all met for <TaskInstance: covid_dag.csv_to_table 2020-06-03T07:51:04.028764+00:00 [queued]>
[2020-06-03 13:35:36,811] {taskinstance.py:879} INFO - 
--------------------------------------------------------------------------------
[2020-06-03 13:35:36,811] {taskinstance.py:880} INFO - Starting attempt 3 of 11
[2020-06-03 13:35:36,812] {taskinstance.py:881} INFO - 
--------------------------------------------------------------------------------
[2020-06-03 13:35:36,819] {taskinstance.py:900} INFO - Executing <Task(PythonOperator): csv_to_table> on 2020-06-03T07:51:04.028764+00:00
[2020-06-03 13:35:36,822] {standard_task_runner.py:53} INFO - Started process 9768 to run task
[2020-06-03 13:35:36,857] {logging_mixin.py:112} INFO - Running %s on host %s <TaskInstance: covid_dag.csv_to_table 2020-06-03T07:51:04.028764+00:00 [running]> nineleaps-ThinkPad-L470
[2020-06-03 13:35:36,865] {taskinstance.py:1145} ERROR - [Errno 2] File b'/home/nineleaps/Data/CovidData_02-Jun-20.csv' does not exist: b'/home/nineleaps/Data/CovidData_02-Jun-20.csv'
Traceback (most recent call last):
  File "/home/nineleaps/.local/lib/python3.6/site-packages/airflow/models/taskinstance.py", line 983, in _run_raw_task
    result = task_copy.execute(context=context)
  File "/home/nineleaps/.local/lib/python3.6/site-packages/airflow/operators/python_operator.py", line 113, in execute
    return_value = self.execute_callable()
  File "/home/nineleaps/.local/lib/python3.6/site-packages/airflow/operators/python_operator.py", line 118, in execute_callable
    return self.python_callable(*self.op_args, **self.op_kwargs)
  File "/home/nineleaps/airflow/dags/covid_dag.py", line 41, in csv_to_table
    data = pd.read_csv('/home/nineleaps/Data/CovidData_' + yest_date.strftime("%d-%b-%y") + '.csv')
  File "/home/nineleaps/.local/lib/python3.6/site-packages/pandas/io/parsers.py", line 685, in parser_f
    return _read(filepath_or_buffer, kwds)
  File "/home/nineleaps/.local/lib/python3.6/site-packages/pandas/io/parsers.py", line 457, in _read
    parser = TextFileReader(fp_or_buf, **kwds)
  File "/home/nineleaps/.local/lib/python3.6/site-packages/pandas/io/parsers.py", line 895, in __init__
    self._make_engine(self.engine)
  File "/home/nineleaps/.local/lib/python3.6/site-packages/pandas/io/parsers.py", line 1135, in _make_engine
    self._engine = CParserWrapper(self.f, **self.options)
  File "/home/nineleaps/.local/lib/python3.6/site-packages/pandas/io/parsers.py", line 1917, in __init__
    self._reader = parsers.TextReader(src, **kwds)
  File "pandas/_libs/parsers.pyx", line 382, in pandas._libs.parsers.TextReader.__cinit__
  File "pandas/_libs/parsers.pyx", line 689, in pandas._libs.parsers.TextReader._setup_parser_source
FileNotFoundError: [Errno 2] File b'/home/nineleaps/Data/CovidData_02-Jun-20.csv' does not exist: b'/home/nineleaps/Data/CovidData_02-Jun-20.csv'
[2020-06-03 13:35:36,867] {taskinstance.py:1168} INFO - Marking task as UP_FOR_RETRY
[2020-06-03 13:35:46,793] {logging_mixin.py:112} INFO - [2020-06-03 13:35:46,792] {local_task_job.py:103} INFO - Task exited with return code 1
