[2020-06-03 13:36:51,866] {taskinstance.py:669} INFO - Dependencies all met for <TaskInstance: covid_dag.csv_to_table 2020-06-03T07:51:04.028764+00:00 [queued]>
[2020-06-03 13:36:51,875] {taskinstance.py:669} INFO - Dependencies all met for <TaskInstance: covid_dag.csv_to_table 2020-06-03T07:51:04.028764+00:00 [queued]>
[2020-06-03 13:36:51,875] {taskinstance.py:879} INFO - 
--------------------------------------------------------------------------------
[2020-06-03 13:36:51,875] {taskinstance.py:880} INFO - Starting attempt 4 of 11
[2020-06-03 13:36:51,875] {taskinstance.py:881} INFO - 
--------------------------------------------------------------------------------
[2020-06-03 13:36:51,883] {taskinstance.py:900} INFO - Executing <Task(PythonOperator): csv_to_table> on 2020-06-03T07:51:04.028764+00:00
[2020-06-03 13:36:51,885] {standard_task_runner.py:53} INFO - Started process 9910 to run task
[2020-06-03 13:36:51,921] {logging_mixin.py:112} INFO - Running %s on host %s <TaskInstance: covid_dag.csv_to_table 2020-06-03T07:51:04.028764+00:00 [running]> nineleaps-ThinkPad-L470
[2020-06-03 13:36:55,184] {logging_mixin.py:112} INFO - [2020-06-03 13:36:55,183] {_metadata.py:95} INFO - Compute Engine Metadata server unavailable onattempt 1 of 3
[2020-06-03 13:36:55,254] {logging_mixin.py:112} INFO - [2020-06-03 13:36:55,254] {_metadata.py:95} INFO - Compute Engine Metadata server unavailable onattempt 2 of 3
[2020-06-03 13:36:58,259] {logging_mixin.py:112} INFO - [2020-06-03 13:36:58,258] {_metadata.py:95} INFO - Compute Engine Metadata server unavailable onattempt 3 of 3
[2020-06-03 13:37:00,010] {taskinstance.py:1145} ERROR - Please verify that the structure and data types in the DataFrame match the schema of the destination table.
Traceback (most recent call last):
  File "/home/nineleaps/.local/lib/python3.6/site-packages/airflow/models/taskinstance.py", line 983, in _run_raw_task
    result = task_copy.execute(context=context)
  File "/home/nineleaps/.local/lib/python3.6/site-packages/airflow/operators/python_operator.py", line 113, in execute
    return_value = self.execute_callable()
  File "/home/nineleaps/.local/lib/python3.6/site-packages/airflow/operators/python_operator.py", line 118, in execute_callable
    return self.python_callable(*self.op_args, **self.op_kwargs)
  File "/home/nineleaps/airflow/dags/covid_dag.py", line 48, in csv_to_table
    if_exists='append')
  File "/home/nineleaps/.local/lib/python3.6/site-packages/pandas/core/frame.py", line 1523, in to_gbq
    private_key=private_key,
  File "/home/nineleaps/.local/lib/python3.6/site-packages/pandas/io/gbq.py", line 209, in to_gbq
    private_key=private_key,
  File "/home/nineleaps/.local/lib/python3.6/site-packages/pandas_gbq/gbq.py", line 1206, in to_gbq
    "Please verify that the structure and "
pandas_gbq.gbq.InvalidSchema: Please verify that the structure and data types in the DataFrame match the schema of the destination table.
[2020-06-03 13:37:00,028] {taskinstance.py:1168} INFO - Marking task as UP_FOR_RETRY
[2020-06-03 13:37:01,868] {logging_mixin.py:112} INFO - [2020-06-03 13:37:01,868] {local_task_job.py:103} INFO - Task exited with return code 1
