[2020-06-05 18:50:32,918] {taskinstance.py:669} INFO - Dependencies all met for <TaskInstance: covid_india_dag.source_to_csv 2020-06-05T13:19:00.882578+00:00 [queued]>
[2020-06-05 18:50:32,926] {taskinstance.py:669} INFO - Dependencies all met for <TaskInstance: covid_india_dag.source_to_csv 2020-06-05T13:19:00.882578+00:00 [queued]>
[2020-06-05 18:50:32,926] {taskinstance.py:879} INFO - 
--------------------------------------------------------------------------------
[2020-06-05 18:50:32,926] {taskinstance.py:880} INFO - Starting attempt 2 of 2
[2020-06-05 18:50:32,926] {taskinstance.py:881} INFO - 
--------------------------------------------------------------------------------
[2020-06-05 18:50:32,935] {taskinstance.py:900} INFO - Executing <Task(PythonOperator): source_to_csv> on 2020-06-05T13:19:00.882578+00:00
[2020-06-05 18:50:32,941] {standard_task_runner.py:53} INFO - Started process 32677 to run task
[2020-06-05 18:50:32,990] {logging_mixin.py:112} INFO - Running %s on host %s <TaskInstance: covid_india_dag.source_to_csv 2020-06-05T13:19:00.882578+00:00 [running]> nineleaps-ThinkPad-L470
[2020-06-05 18:50:33,432] {logging_mixin.py:112} INFO - [2020-06-05 18:50:33,431] {covid_india_dag.py:50} ERROR - Http Error: 404 Client Error: Not Found for url: https://api.covid19india.org/states_daily.jso
[2020-06-05 18:50:33,965] {taskinstance.py:1145} ERROR - Can only merge Series or DataFrame objects, a <class 'NoneType'> was passed
Traceback (most recent call last):
  File "/home/nineleaps/.local/lib/python3.6/site-packages/airflow/models/taskinstance.py", line 983, in _run_raw_task
    result = task_copy.execute(context=context)
  File "/home/nineleaps/.local/lib/python3.6/site-packages/airflow/operators/python_operator.py", line 113, in execute
    return_value = self.execute_callable()
  File "/home/nineleaps/.local/lib/python3.6/site-packages/airflow/operators/python_operator.py", line 118, in execute_callable
    return self.python_callable(*self.op_args, **self.op_kwargs)
  File "/home/nineleaps/airflow/dags/covid_india_dag.py", line 84, in source_to_csv
    data = get_covid_data()
  File "/home/nineleaps/airflow/dags/covid_india_dag.py", line 78, in get_covid_data
    covid_data = pd.merge(confirmed_case_df, state_list_df, on='statecode')
  File "/home/nineleaps/.local/lib/python3.6/site-packages/pandas/core/reshape/merge.py", line 81, in merge
    validate=validate,
  File "/home/nineleaps/.local/lib/python3.6/site-packages/pandas/core/reshape/merge.py", line 571, in __init__
    left = validate_operand(left)
  File "/home/nineleaps/.local/lib/python3.6/site-packages/pandas/core/reshape/merge.py", line 1993, in validate_operand
    "a {obj} was passed".format(obj=type(obj))
TypeError: Can only merge Series or DataFrame objects, a <class 'NoneType'> was passed
[2020-06-05 18:50:33,968] {taskinstance.py:1187} INFO - All retries failed; marking task as FAILED.dag_id=covid_india_dag, task_id=source_to_csv, execution_date=20200605T131900, start_date=20200605T132032, end_date=20200605T132033
[2020-06-05 18:50:35,673] {logging_mixin.py:112} INFO - [2020-06-05 18:50:35,672] {email.py:131} INFO - Sent an alert email to ['captaincold268@gmail.com']
[2020-06-05 18:50:42,916] {logging_mixin.py:112} INFO - [2020-06-05 18:50:42,914] {local_task_job.py:103} INFO - Task exited with return code 1
