[2020-06-05 12:42:19,184] {taskinstance.py:669} INFO - Dependencies all met for <TaskInstance: covid_india_dag.source_to_csv 2020-06-05T07:06:12.908617+00:00 [queued]>
[2020-06-05 12:42:19,194] {taskinstance.py:669} INFO - Dependencies all met for <TaskInstance: covid_india_dag.source_to_csv 2020-06-05T07:06:12.908617+00:00 [queued]>
[2020-06-05 12:42:19,194] {taskinstance.py:879} INFO - 
--------------------------------------------------------------------------------
[2020-06-05 12:42:19,194] {taskinstance.py:880} INFO - Starting attempt 2 of 2
[2020-06-05 12:42:19,194] {taskinstance.py:881} INFO - 
--------------------------------------------------------------------------------
[2020-06-05 12:42:19,204] {taskinstance.py:900} INFO - Executing <Task(PythonOperator): source_to_csv> on 2020-06-05T07:06:12.908617+00:00
[2020-06-05 12:42:19,206] {standard_task_runner.py:53} INFO - Started process 1618 to run task
[2020-06-05 12:42:19,240] {logging_mixin.py:112} INFO - Running %s on host %s <TaskInstance: covid_india_dag.source_to_csv 2020-06-05T07:06:12.908617+00:00 [running]> nineleaps-ThinkPad-L470
[2020-06-05 12:42:19,614] {taskinstance.py:1145} ERROR - 404 Client Error: Not Found for url: https://api.covid19india.org/states_daily.jso
Traceback (most recent call last):
  File "/home/nineleaps/.local/lib/python3.6/site-packages/airflow/models/taskinstance.py", line 983, in _run_raw_task
    result = task_copy.execute(context=context)
  File "/home/nineleaps/.local/lib/python3.6/site-packages/airflow/operators/python_operator.py", line 113, in execute
    return_value = self.execute_callable()
  File "/home/nineleaps/.local/lib/python3.6/site-packages/airflow/operators/python_operator.py", line 118, in execute_callable
    return self.python_callable(*self.op_args, **self.op_kwargs)
  File "/home/nineleaps/airflow/dags/Covid_India_SampleDag.py", line 66, in source_to_csv
    data = get_covid_data()
  File "/home/nineleaps/airflow/dags/Covid_India_SampleDag.py", line 58, in get_covid_data
    confirmed_case_df = get_confirmed_cases()
  File "/home/nineleaps/airflow/dags/Covid_India_SampleDag.py", line 34, in get_confirmed_cases
    r.raise_for_status()
  File "/home/nineleaps/.local/lib/python3.6/site-packages/requests/models.py", line 941, in raise_for_status
    raise HTTPError(http_error_msg, response=self)
requests.exceptions.HTTPError: 404 Client Error: Not Found for url: https://api.covid19india.org/states_daily.jso
[2020-06-05 12:42:19,617] {taskinstance.py:1187} INFO - All retries failed; marking task as FAILED.dag_id=covid_india_dag, task_id=source_to_csv, execution_date=20200605T070612, start_date=20200605T071219, end_date=20200605T071219
[2020-06-05 12:42:21,766] {logging_mixin.py:112} INFO - [2020-06-05 12:42:21,765] {email.py:131} INFO - Sent an alert email to ['captaincold268@gmail.com']
[2020-06-05 12:42:24,204] {logging_mixin.py:112} INFO - [2020-06-05 12:42:24,203] {local_task_job.py:167} WARNING - State of this instance has been externally set to failed. Taking the poison pill.
[2020-06-05 12:42:24,250] {helpers.py:325} INFO - Sending Signals.SIGTERM to GPID 1618
[2020-06-05 12:42:24,251] {helpers.py:291} INFO - Process psutil.Process(pid=1618, status='terminated') (1618) terminated with exit code 1
[2020-06-05 12:42:29,183] {logging_mixin.py:112} INFO - [2020-06-05 12:42:29,183] {local_task_job.py:103} INFO - Task exited with return code 1
