[2020-06-05 16:56:32,879] {taskinstance.py:669} INFO - Dependencies all met for <TaskInstance: covid_india_dag.source_to_csv 2020-06-05T11:26:07.183168+00:00 [queued]>
[2020-06-05 16:56:32,885] {taskinstance.py:669} INFO - Dependencies all met for <TaskInstance: covid_india_dag.source_to_csv 2020-06-05T11:26:07.183168+00:00 [queued]>
[2020-06-05 16:56:32,885] {taskinstance.py:879} INFO - 
--------------------------------------------------------------------------------
[2020-06-05 16:56:32,885] {taskinstance.py:880} INFO - Starting attempt 1 of 2
[2020-06-05 16:56:32,885] {taskinstance.py:881} INFO - 
--------------------------------------------------------------------------------
[2020-06-05 16:56:32,894] {taskinstance.py:900} INFO - Executing <Task(PythonOperator): source_to_csv> on 2020-06-05T11:26:07.183168+00:00
[2020-06-05 16:56:32,896] {standard_task_runner.py:53} INFO - Started process 22228 to run task
[2020-06-05 16:56:32,931] {logging_mixin.py:112} INFO - Running %s on host %s <TaskInstance: covid_india_dag.source_to_csv 2020-06-05T11:26:07.183168+00:00 [running]> nineleaps-ThinkPad-L470
[2020-06-05 16:56:33,637] {logging_mixin.py:112} INFO - [2020-06-05 16:56:33,634] {Covid_India_SampleDag.py:48} ERROR - Http Error: 404 Client Error: Not Found for url: https://api.covid19india.org/states_daily.jso
[2020-06-05 16:56:34,231] {taskinstance.py:1145} ERROR - Can only merge Series or DataFrame objects, a <class 'NoneType'> was passed
Traceback (most recent call last):
  File "/home/nineleaps/.local/lib/python3.6/site-packages/airflow/models/taskinstance.py", line 983, in _run_raw_task
    result = task_copy.execute(context=context)
  File "/home/nineleaps/.local/lib/python3.6/site-packages/airflow/operators/python_operator.py", line 113, in execute
    return_value = self.execute_callable()
  File "/home/nineleaps/.local/lib/python3.6/site-packages/airflow/operators/python_operator.py", line 118, in execute_callable
    return self.python_callable(*self.op_args, **self.op_kwargs)
  File "/home/nineleaps/airflow/dags/Covid_India_SampleDag.py", line 84, in source_to_csv
    data = get_covid_data()
  File "/home/nineleaps/airflow/dags/Covid_India_SampleDag.py", line 78, in get_covid_data
    covid_data = pd.merge(confirmed_case_df, state_list_df, on='statecode')
  File "/home/nineleaps/.local/lib/python3.6/site-packages/pandas/core/reshape/merge.py", line 81, in merge
    validate=validate,
  File "/home/nineleaps/.local/lib/python3.6/site-packages/pandas/core/reshape/merge.py", line 571, in __init__
    left = validate_operand(left)
  File "/home/nineleaps/.local/lib/python3.6/site-packages/pandas/core/reshape/merge.py", line 1993, in validate_operand
    "a {obj} was passed".format(obj=type(obj))
TypeError: Can only merge Series or DataFrame objects, a <class 'NoneType'> was passed
[2020-06-05 16:56:34,247] {taskinstance.py:1168} INFO - Marking task as UP_FOR_RETRY
[2020-06-05 16:56:36,578] {logging_mixin.py:112} INFO - [2020-06-05 16:56:36,578] {email.py:131} INFO - Sent an alert email to ['captaincold268@gmail.com']
[2020-06-05 16:56:42,885] {logging_mixin.py:112} INFO - [2020-06-05 16:56:42,884] {local_task_job.py:103} INFO - Task exited with return code 1
