[2020-06-05 16:57:34,511] {taskinstance.py:669} INFO - Dependencies all met for <TaskInstance: covid_india_dag.source_to_csv 2020-06-05T11:26:07.183168+00:00 [queued]>
[2020-06-05 16:57:34,517] {taskinstance.py:669} INFO - Dependencies all met for <TaskInstance: covid_india_dag.source_to_csv 2020-06-05T11:26:07.183168+00:00 [queued]>
[2020-06-05 16:57:34,517] {taskinstance.py:879} INFO - 
--------------------------------------------------------------------------------
[2020-06-05 16:57:34,517] {taskinstance.py:880} INFO - Starting attempt 2 of 2
[2020-06-05 16:57:34,517] {taskinstance.py:881} INFO - 
--------------------------------------------------------------------------------
[2020-06-05 16:57:34,534] {taskinstance.py:900} INFO - Executing <Task(PythonOperator): source_to_csv> on 2020-06-05T11:26:07.183168+00:00
[2020-06-05 16:57:34,538] {standard_task_runner.py:53} INFO - Started process 22374 to run task
[2020-06-05 16:57:34,589] {logging_mixin.py:112} INFO - Running %s on host %s <TaskInstance: covid_india_dag.source_to_csv 2020-06-05T11:26:07.183168+00:00 [running]> nineleaps-ThinkPad-L470
[2020-06-05 16:57:35,262] {logging_mixin.py:112} INFO - [2020-06-05 16:57:35,260] {Covid_India_SampleDag.py:48} ERROR - Http Error: 404 Client Error: Not Found for url: https://api.covid19india.org/states_daily.jso
[2020-06-05 16:57:35,738] {taskinstance.py:1145} ERROR - Can only merge Series or DataFrame objects, a <class 'NoneType'> was passed
Traceback (most recent call last):
  File "/home/nineleaps/.local/lib/python3.6/site-packages/airflow/models/taskinstance.py", line 983, in _run_raw_task
    result = task_copy.execute(context=context)
  File "/home/nineleaps/.local/lib/python3.6/site-packages/airflow/operators/python_operator.py", line 113, in execute
    return_value = self.execute_callable()
  File "/home/nineleaps/.local/lib/python3.6/site-packages/airflow/operators/python_operator.py", line 118, in execute_callable
    return self.python_callable(*self.op_args, **self.op_kwargs)
  File "/home/nineleaps/airflow/dags/Covid_India_SampleDag.py", line 84, in source_to_csv
    data = get_covid_data()
  File "/home/nineleaps/airflow/dags/Covid_India_SampleDag.py", line 78, in get_covid_data
    covid_data = pd.merge(confirmed_case_df, state_list_df, on='statecode')
  File "/home/nineleaps/.local/lib/python3.6/site-packages/pandas/core/reshape/merge.py", line 81, in merge
    validate=validate,
  File "/home/nineleaps/.local/lib/python3.6/site-packages/pandas/core/reshape/merge.py", line 571, in __init__
    left = validate_operand(left)
  File "/home/nineleaps/.local/lib/python3.6/site-packages/pandas/core/reshape/merge.py", line 1993, in validate_operand
    "a {obj} was passed".format(obj=type(obj))
TypeError: Can only merge Series or DataFrame objects, a <class 'NoneType'> was passed
[2020-06-05 16:57:35,747] {taskinstance.py:1187} INFO - All retries failed; marking task as FAILED.dag_id=covid_india_dag, task_id=source_to_csv, execution_date=20200605T112607, start_date=20200605T112734, end_date=20200605T112735
[2020-06-05 16:57:37,788] {logging_mixin.py:112} INFO - [2020-06-05 16:57:37,787] {email.py:131} INFO - Sent an alert email to ['captaincold268@gmail.com']
[2020-06-05 16:57:44,511] {logging_mixin.py:112} INFO - [2020-06-05 16:57:44,510] {local_task_job.py:103} INFO - Task exited with return code 1
