[2020-06-04 17:30:32,512] {taskinstance.py:669} INFO - Dependencies all met for <TaskInstance: covid_india_dag.source_to_csv 2020-06-04T11:58:39.653687+00:00 [queued]>
[2020-06-04 17:30:32,520] {taskinstance.py:669} INFO - Dependencies all met for <TaskInstance: covid_india_dag.source_to_csv 2020-06-04T11:58:39.653687+00:00 [queued]>
[2020-06-04 17:30:32,520] {taskinstance.py:879} INFO - 
--------------------------------------------------------------------------------
[2020-06-04 17:30:32,520] {taskinstance.py:880} INFO - Starting attempt 2 of 2
[2020-06-04 17:30:32,520] {taskinstance.py:881} INFO - 
--------------------------------------------------------------------------------
[2020-06-04 17:30:32,528] {taskinstance.py:900} INFO - Executing <Task(PythonOperator): source_to_csv> on 2020-06-04T11:58:39.653687+00:00
[2020-06-04 17:30:32,531] {standard_task_runner.py:53} INFO - Started process 22146 to run task
[2020-06-04 17:30:32,568] {logging_mixin.py:112} INFO - Running %s on host %s <TaskInstance: covid_india_dag.source_to_csv 2020-06-04T11:58:39.653687+00:00 [running]> nineleaps-ThinkPad-L470
[2020-06-04 17:30:33,036] {taskinstance.py:1145} ERROR - name 'get_state_list' is not defined
Traceback (most recent call last):
  File "/home/nineleaps/.local/lib/python3.6/site-packages/airflow/models/taskinstance.py", line 983, in _run_raw_task
    result = task_copy.execute(context=context)
  File "/home/nineleaps/.local/lib/python3.6/site-packages/airflow/operators/python_operator.py", line 113, in execute
    return_value = self.execute_callable()
  File "/home/nineleaps/.local/lib/python3.6/site-packages/airflow/operators/python_operator.py", line 118, in execute_callable
    return self.python_callable(*self.op_args, **self.op_kwargs)
  File "/home/nineleaps/airflow/dags/Covid_India_SampleDag.py", line 63, in source_to_csv
    data = get_covid_data()
  File "/home/nineleaps/airflow/dags/Covid_India_SampleDag.py", line 56, in get_covid_data
    state_list_df = get_state_list()
NameError: name 'get_state_list' is not defined
[2020-06-04 17:30:33,038] {taskinstance.py:1187} INFO - All retries failed; marking task as FAILED.dag_id=covid_india_dag, task_id=source_to_csv, execution_date=20200604T115839, start_date=20200604T120032, end_date=20200604T120033
[2020-06-04 17:30:34,762] {logging_mixin.py:112} INFO - [2020-06-04 17:30:34,761] {email.py:131} INFO - Sent an alert email to ['shanonbeatrice28797@gmail.com']
[2020-06-04 17:30:42,519] {logging_mixin.py:112} INFO - [2020-06-04 17:30:42,518] {local_task_job.py:103} INFO - Task exited with return code 1
