[2020-06-04 16:38:29,237] {taskinstance.py:669} INFO - Dependencies all met for <TaskInstance: covid_india_dag.source_to_csv 2020-06-04T11:07:50.438792+00:00 [queued]>
[2020-06-04 16:38:29,244] {taskinstance.py:669} INFO - Dependencies all met for <TaskInstance: covid_india_dag.source_to_csv 2020-06-04T11:07:50.438792+00:00 [queued]>
[2020-06-04 16:38:29,244] {taskinstance.py:879} INFO - 
--------------------------------------------------------------------------------
[2020-06-04 16:38:29,244] {taskinstance.py:880} INFO - Starting attempt 1 of 2
[2020-06-04 16:38:29,244] {taskinstance.py:881} INFO - 
--------------------------------------------------------------------------------
[2020-06-04 16:38:29,253] {taskinstance.py:900} INFO - Executing <Task(PythonOperator): source_to_csv> on 2020-06-04T11:07:50.438792+00:00
[2020-06-04 16:38:29,258] {standard_task_runner.py:53} INFO - Started process 16846 to run task
[2020-06-04 16:38:29,315] {logging_mixin.py:112} INFO - Running %s on host %s <TaskInstance: covid_india_dag.source_to_csv 2020-06-04T11:07:50.438792+00:00 [running]> nineleaps-ThinkPad-L470
[2020-06-04 16:38:30,093] {taskinstance.py:1145} ERROR - name 'get_state_list' is not defined
Traceback (most recent call last):
  File "/home/nineleaps/.local/lib/python3.6/site-packages/airflow/models/taskinstance.py", line 983, in _run_raw_task
    result = task_copy.execute(context=context)
  File "/home/nineleaps/.local/lib/python3.6/site-packages/airflow/operators/python_operator.py", line 113, in execute
    return_value = self.execute_callable()
  File "/home/nineleaps/.local/lib/python3.6/site-packages/airflow/operators/python_operator.py", line 118, in execute_callable
    return self.python_callable(*self.op_args, **self.op_kwargs)
  File "/home/nineleaps/airflow/dags/Covid_India_SampleDag.py", line 61, in source_to_csv
    data = get_covid_data()
  File "/home/nineleaps/airflow/dags/Covid_India_SampleDag.py", line 55, in get_covid_data
    state_list_df = get_state_list()
NameError: name 'get_state_list' is not defined
[2020-06-04 16:38:30,096] {taskinstance.py:1168} INFO - Marking task as UP_FOR_RETRY
[2020-06-04 16:38:30,120] {logging_mixin.py:112} INFO - [2020-06-04 16:38:30,120] {configuration.py:320} WARNING - section/key [smtp/smtp_user] not found in config
[2020-06-04 16:38:30,123] {logging_mixin.py:112} INFO - [2020-06-04 16:38:30,122] {configuration.py:320} WARNING - section/key [smtp/smtp_user] not found in config
[2020-06-04 16:38:30,123] {taskinstance.py:1206} ERROR - Failed to send email to: ['varunprabhakar26@gmail.com']
[2020-06-04 16:38:30,123] {taskinstance.py:1207} ERROR - [Errno 111] Connection refused
Traceback (most recent call last):
  File "/home/nineleaps/.local/lib/python3.6/site-packages/airflow/models/taskinstance.py", line 983, in _run_raw_task
    result = task_copy.execute(context=context)
  File "/home/nineleaps/.local/lib/python3.6/site-packages/airflow/operators/python_operator.py", line 113, in execute
    return_value = self.execute_callable()
  File "/home/nineleaps/.local/lib/python3.6/site-packages/airflow/operators/python_operator.py", line 118, in execute_callable
    return self.python_callable(*self.op_args, **self.op_kwargs)
  File "/home/nineleaps/airflow/dags/Covid_India_SampleDag.py", line 61, in source_to_csv
    data = get_covid_data()
  File "/home/nineleaps/airflow/dags/Covid_India_SampleDag.py", line 55, in get_covid_data
    state_list_df = get_state_list()
NameError: name 'get_state_list' is not defined

During handling of the above exception, another exception occurred:

Traceback (most recent call last):
  File "/home/nineleaps/.local/lib/python3.6/site-packages/airflow/models/taskinstance.py", line 1475, in email_alert
    send_email(self.task.email, subject, html_content)
  File "/home/nineleaps/.local/lib/python3.6/site-packages/airflow/utils/email.py", line 60, in send_email
    mime_subtype=mime_subtype, mime_charset=mime_charset, **kwargs)
  File "/home/nineleaps/.local/lib/python3.6/site-packages/airflow/utils/email.py", line 106, in send_email_smtp
    send_MIME_email(smtp_mail_from, recipients, msg, dryrun)
  File "/home/nineleaps/.local/lib/python3.6/site-packages/airflow/utils/email.py", line 126, in send_MIME_email
    s = smtplib.SMTP_SSL(SMTP_HOST, SMTP_PORT) if SMTP_SSL else smtplib.SMTP(SMTP_HOST, SMTP_PORT)
  File "/usr/lib/python3.6/smtplib.py", line 251, in __init__
    (code, msg) = self.connect(host, port)
  File "/usr/lib/python3.6/smtplib.py", line 336, in connect
    self.sock = self._get_socket(host, port, self.timeout)
  File "/usr/lib/python3.6/smtplib.py", line 307, in _get_socket
    self.source_address)
  File "/usr/lib/python3.6/socket.py", line 724, in create_connection
    raise err
  File "/usr/lib/python3.6/socket.py", line 713, in create_connection
    sock.connect(sa)
ConnectionRefusedError: [Errno 111] Connection refused

During handling of the above exception, another exception occurred:

Traceback (most recent call last):
  File "/home/nineleaps/.local/lib/python3.6/site-packages/airflow/models/taskinstance.py", line 1170, in handle_failure
    self.email_alert(error)
  File "/home/nineleaps/.local/lib/python3.6/site-packages/airflow/models/taskinstance.py", line 1477, in email_alert
    send_email(self.task.email, subject, html_content_err)
  File "/home/nineleaps/.local/lib/python3.6/site-packages/airflow/utils/email.py", line 60, in send_email
    mime_subtype=mime_subtype, mime_charset=mime_charset, **kwargs)
  File "/home/nineleaps/.local/lib/python3.6/site-packages/airflow/utils/email.py", line 106, in send_email_smtp
    send_MIME_email(smtp_mail_from, recipients, msg, dryrun)
  File "/home/nineleaps/.local/lib/python3.6/site-packages/airflow/utils/email.py", line 126, in send_MIME_email
    s = smtplib.SMTP_SSL(SMTP_HOST, SMTP_PORT) if SMTP_SSL else smtplib.SMTP(SMTP_HOST, SMTP_PORT)
  File "/usr/lib/python3.6/smtplib.py", line 251, in __init__
    (code, msg) = self.connect(host, port)
  File "/usr/lib/python3.6/smtplib.py", line 336, in connect
    self.sock = self._get_socket(host, port, self.timeout)
  File "/usr/lib/python3.6/smtplib.py", line 307, in _get_socket
    self.source_address)
  File "/usr/lib/python3.6/socket.py", line 724, in create_connection
    raise err
  File "/usr/lib/python3.6/socket.py", line 713, in create_connection
    sock.connect(sa)
ConnectionRefusedError: [Errno 111] Connection refused
[2020-06-04 16:38:39,243] {logging_mixin.py:112} INFO - [2020-06-04 16:38:39,242] {local_task_job.py:103} INFO - Task exited with return code 1
