[2020-06-09 12:59:51,515] {taskinstance.py:669} INFO - Dependencies all met for <TaskInstance: covid_india_dag.source_to_csv 2020-06-09T07:23:55.322252+00:00 [queued]>
[2020-06-09 12:59:51,521] {taskinstance.py:669} INFO - Dependencies all met for <TaskInstance: covid_india_dag.source_to_csv 2020-06-09T07:23:55.322252+00:00 [queued]>
[2020-06-09 12:59:51,521] {taskinstance.py:879} INFO - 
--------------------------------------------------------------------------------
[2020-06-09 12:59:51,521] {taskinstance.py:880} INFO - Starting attempt 2 of 2
[2020-06-09 12:59:51,521] {taskinstance.py:881} INFO - 
--------------------------------------------------------------------------------
[2020-06-09 12:59:51,529] {taskinstance.py:900} INFO - Executing <Task(PythonOperator): source_to_csv> on 2020-06-09T07:23:55.322252+00:00
[2020-06-09 12:59:51,531] {standard_task_runner.py:53} INFO - Started process 12299 to run task
[2020-06-09 12:59:51,572] {logging_mixin.py:112} INFO - Running %s on host %s <TaskInstance: covid_india_dag.source_to_csv 2020-06-09T07:23:55.322252+00:00 [running]> nineleaps-ThinkPad-L470
[2020-06-09 12:59:52,193] {logging_mixin.py:112} INFO - [2020-06-09 12:59:52,191] {covid_india_dag.py:50} ERROR - Http Error: 404 Client Error: Not Found for url: https://api.covid19india.org/states_daily.jso
[2020-06-09 12:59:52,194] {taskinstance.py:1145} ERROR - 404 Client Error: Not Found for url: https://api.covid19india.org/states_daily.jso
Traceback (most recent call last):
  File "/home/nineleaps/.local/lib/python3.6/site-packages/airflow/models/taskinstance.py", line 983, in _run_raw_task
    result = task_copy.execute(context=context)
  File "/home/nineleaps/.local/lib/python3.6/site-packages/airflow/operators/python_operator.py", line 113, in execute
    return_value = self.execute_callable()
  File "/home/nineleaps/.local/lib/python3.6/site-packages/airflow/operators/python_operator.py", line 118, in execute_callable
    return self.python_callable(*self.op_args, **self.op_kwargs)
  File "/home/nineleaps/airflow/dags/covid_india_dag.py", line 90, in source_to_csv
    data = get_covid_data()
  File "/home/nineleaps/airflow/dags/covid_india_dag.py", line 82, in get_covid_data
    confirmed_case_df = get_confirmed_cases()
  File "/home/nineleaps/airflow/dags/covid_india_dag.py", line 39, in get_confirmed_cases
    r.raise_for_status()
  File "/home/nineleaps/.local/lib/python3.6/site-packages/requests/models.py", line 941, in raise_for_status
    raise HTTPError(http_error_msg, response=self)
requests.exceptions.HTTPError: 404 Client Error: Not Found for url: https://api.covid19india.org/states_daily.jso
[2020-06-09 12:59:52,199] {taskinstance.py:1187} INFO - All retries failed; marking task as FAILED.dag_id=covid_india_dag, task_id=source_to_csv, execution_date=20200609T072355, start_date=20200609T072951, end_date=20200609T072952
[2020-06-09 12:59:54,225] {logging_mixin.py:112} INFO - [2020-06-09 12:59:54,224] {email.py:131} INFO - Sent an alert email to ['captaincold268@gmail.com']
[2020-06-09 12:59:56,524] {logging_mixin.py:112} INFO - [2020-06-09 12:59:56,523] {local_task_job.py:167} WARNING - State of this instance has been externally set to failed. Taking the poison pill.
[2020-06-09 12:59:56,536] {helpers.py:325} INFO - Sending Signals.SIGTERM to GPID 12299
[2020-06-09 12:59:56,536] {helpers.py:291} INFO - Process psutil.Process(pid=12299, status='terminated') (12299) terminated with exit code 1
[2020-06-09 13:00:01,516] {logging_mixin.py:112} INFO - [2020-06-09 13:00:01,515] {local_task_job.py:103} INFO - Task exited with return code 1
